# 210830 : nodejs 비동기 처리, promise
## 비동기 처리
참고링크 : https://joshua1988.github.io/web-development/javascript/javascript-asynchronous-operation/</br>
참고링크 : https://joshua1988.github.io/web-development/javascript/promise-for-beginners/</br>

비동기 처리란 코드가 실행될때 큐와 유사하게 앞에 코드의 실행이 완료되면 그 다음 코드가 실행되는 것이 아니고,
앞에 코드에서 실행 지연이 있더라도 다음 코드로 가서 실행을 이어나가는 것을 말한다.

```
function getData() {
	var tableData;
	$.get('https://domain.com/products/1', function(response) {
		tableData = response;
	});
	return tableData;
}

console.log(getData()); //undefined
```
 위 함수의 실행은 `undefined`를 출력한다. 왜냐하면 자바스크립트는 비동기 처리를 기본으로 하기 때문에,</br>
 get() 함수의 실행이 끝날때 까지 기다리지 않고 바로 return tableData로 넘아가게 된다.</br>
 아직 tableData는 null인 상태이므로 console.log()에서 undefined를 출력하게 되는 것이다.</br>
 이를 해결하기 위해서는 콜백함수를 사용하여 동기적으로 처리해야 한다.</br>
 
```
function getData(callbackFunc) {
	$.get('https://domain.com/products/1', function(response) {
		callbackFunc(response); 
	});
}

getData(function(tableData) {
	console.log(tableData); //
});
```

위 코드에서 getData() 함수의 실행이 종료되면 콜백함수가 호출되게 된다.

## Promise
promise는 비동기 처리 문제를 해결하기 위한 방법이다. Promise는 객체이다.

```
function getData(callback) {
  return new Promise(function(resolve, reject) {
    $.get('url 주소/products/1', function(response) {
      resolve(response);
    });
  });
}

getData().then(function(tableData) {
  console.log(tableData); // $.get()의 reponse 값이 tableData에 전달됨
});
```
위 코드에서 Promise()안에는 함수가 들어있다. 이 함수가 실행되면 $.get()함수가 실행되고 url을 통해 데이터를 불러오게 되면,
콜백함수가 실행된다. 이때 resolve()는 promise가 정상적으로 실행되었을 때 호출된다. resolve가 호출되면 getData().then()이 실행된다.
response는 tableData에 담겨져 출력된다.

### promise의 상태

promise는 총 3개의 상태를 가지고 있다.
- Pending(대기) : 비동기 처리 로직이 아직 완료되지 않은 상태
- Fulfilled(이행) : 비동기 처리가 완료되어 프로미스가 결과 값을 반환해준 상태
- Rejected(실패) : 비동기 처리가 실패하거나 오류가 발생한 상태

`Promise()`를 호출하면 대기상태로 들어간다.
`resolove()`를 호출하면 이행상태로 들어간다.
`reject()`를 호출하면 실패상태로 들어간다.

```
function getData() {
  return new Promise(function(resolve, reject) {
    $.get('url 주소/products/1', function(response) {
      if (response) {
        resolve(response);
      }
      reject(new Error("Request is failed"));
    });
  });
}

getData().then(function(data) {
  console.log(data);
}).catch(function(err) {
  console.error(err);
});
```
위 코드는 에러처리를 추가한 코드이다. $.get()에서 url을 타고 불러온 데이터가 정상적이라면 resolve()를 호출하여 then()에 담긴 콜백함수가 실행될 것이다.</br>
만약 그렇지 않다면 reject()가 실행되어 getData()뒤에 catch()가 실행되어 에러를 잡아줄 것이다.</br>

 promise를 사용하는 방법에는 두가지가 있다. 첫번째는 then()에 성공했을 때의 콜백함수와, 실패했을 때의 콜백함수를 넣는 방법이며,</br>
 두번째는 위 코드처럼 catch()를 사용하는 것이다.</br>
 첫번째 방법의 경우 성공시의 콜백함수에서 에러가 발생했을 때의 에러처리를 하지 못한다는 단점이 있다.</br>
 반면에 두번째 방법은 성공시의 콜백함수에서 에러가 발생하게되면 catch()가 실행되어 에러를 잡아준다.</br>
 따라서 참고한 사이트의 저자인 `캡틴판교`님의 말에 따르면 두번째 방법을 추천한다고 한다.</br>

 
